Workbook

Sheet LEEME
A1: Base de conocimiento de minutas — Asistente Red IDBI
A2: Para qué sirve | B2: Cargar las minutas técnicas hechas a mano (PDF) en la base de datos, con el mismo vocabulario del chat de 76 nodos, para que el motor de recomendaciones aprenda de casos reales.
A3: Qué ya trae | B3: 44 minutas manuales cargadas (MH-001 a MH-044), 67 reglas de recomendación + 13 acciones estándar, 10 reglas de validación, 13 equipos y 27 umbrales.
A4: Cómo agregar una minuta | B4: 1) kb_minuta: una fila nueva con el siguiente minuta_id (MH-045…). 2) kb_minuta_respuesta: lo que el PDF responde de las preguntas del flujo (ver ref_preguntas). 3) kb_minuta_hallazgo: antecedentes, desarrollo y observaciones. 4) kb_minuta_recomendacion: cada recomendación y siguiente acción, con su regla_id. 5) kb_minuta_equipo y kb_minuta_evidencia.
A5: Colores | B5: Amarillo = filas vacías para llenar. Gris = fórmula, no escribir. Azul = encabezado (nombre de columna en la base, no cambiar).
A6: Valores | B6: Usa los códigos de las listas desplegables (hoja catalogos): son los mismos del flujo (ej. FAST_FOOD, CABLE_RED, SI/NO). Si la respuesta es Otro, escribe OTRO: seguido del texto (ej. OTRO: Yachay Telecomunicaciones, OTRO: Cocina 2).
A7: Respuestas | B7: confianza = EXPLICITO si la minuta lo dice tal cual; INFERIDO si se deduce. alcance solo para preguntas que se repiten (L_CAJAS:1, L_IMPRESORAS:2).
A8: Recomendaciones | B8: Cada fila debe tener regla_id. Si ninguna regla calza, crea una nueva en kb_regla_recomendacion (R29, R30…) y úsala. La hoja resumen avisa cuántas quedan sin regla.
A9: Estado del local | B9: P08 ya no es el motivo de visita: es el estado del local (En operación, En obra, Por inaugurar, Ya cuenta con un sistema de punto de venta anterior, Otro). En las minutas cargadas solo se llenó donde la minuta lo deja claro; las demás quedan en blanco.
A10: Pasos a seguir, observaciones y anexos | B10: Los pasos a seguir (cliente / ID) se generan solos y el técnico los edita (hoja kb_accion_siguiente). Después del análisis se abre un apartado de observaciones con selección múltiple: observaciones del técnico, serie de facturación, ¿el cliente acepta la recomendación? (Sí/No/Otro), método de pago y Otro (hoja kb_observacion_opcion). Va en la minuta después de las recomendaciones. Los enlaces de video del local van como anexos (P49a).
A11: Speedtest y WiFi por zona | B11: El speedtest del plan (E1) se hace por cable directo al router principal (Cat6, puerto RJ45 gigabit); por WiFi no vale. V01: la mejor de 2 pruebas por cable debe llegar al 70 % del plan; entre 85 y 95 Mbps con plan mayor = limitada a 100 Mbps (R65); ping con carga > 300 ms = saturación (R66, observación). El WiFi se revisa por zona (opcional) con umbrales para el punto de venta (kb_umbral).
A12: Canales y evidencias | B12: Canales de atención (Mesa, Recojo, Para llevar, Backoffice, Delivery, Otro) con sus zonas sugeridas + Otro (hoja kb_canal_atencion). Fotos obligatorias: frontis, cada lugar de preparación, cada zona de atención y cada caja (hoja kb_evidencia_obligatoria). La IA valida que la foto sea la pedida y legible comparándola con el dataset de referencias (hojas kb_evidencia_tipo y kb_evidencia_referencia).
A13: Prueba retrospectiva | B13: Motor vs. minutas reales: 81.7 % de coincidencia en 126 decisiones comparables (hoja kb_prueba_retrospectiva).
... A23: Detalle técnico | B23: docs/base-conocimiento/BASE_CONOCIMIENTO_MINUTAS.md explica las tablas, el importador y cómo usarlas en las recomendaciones.

Sheet resumen
A1: Indicador | B1: Valor | C1: Cómo se calcula
A2: Minutas cargadas | B2: =COUNTA(kb_minuta!$A$2:$A$2000) | C2: Filas con minuta_id en kb_minuta
A3: Respuestas del flujo extraídas | B3: =COUNTA(kb_minuta_respuesta!$A$2:$A$2000) | C3: Filas en kb_minuta_respuesta
A4: · explícitas | B4: =COUNTIF(kb_minuta_respuesta!$E$2:$E$2000,"EXPLICITO")
A5: · inferidas | B5: =COUNTIF(kb_minuta_respuesta!$E$2:$E$2000,"INFERIDO")
A6: Hallazgos | B6: =COUNTA(kb_minuta_hallazgo!$A$2:$A$2000)
A7: Recomendaciones (sin acciones) | B7: =COUNTIF(kb_minuta_recomendacion!$C$2:$C$2000,"RECOMENDACION")
A8: Siguientes acciones | B8: =COUNTIF(kb_minuta_recomendacion!$C$2:$C$2000,"ACCION*") | C8: ACCION_ID + ACCION_CLIENTE
A9: Recomendaciones sin regla vinculada | B9: =COUNTIFS(kb_minuta_recomendacion!$A$2:$A$2000,"<>",kb_minuta_recomendacion!$D$2:$D$2000,"") | C9: Deben quedar en 0 antes de cargar
A10: Reglas en la base | B10: =COUNTA(kb_regla_recomendacion!$A$2:$A$200)
A11: Reglas respaldadas por al menos una minuta | B11: =COUNTIF(kb_regla_recomendacion!$M$2:$M$200,">0")
A12: Equipos registrados en minutas | B12: =COUNTA(kb_minuta_equipo!$A$2:$A$2000)
A13: Evidencias referenciadas | B13: =COUNTA(kb_minuta_evidencia!$A$2:$A$2000)
A14: Credenciales (confidencial) | B14: =COUNTA(kb_minuta_credencial!$A$2:$A$2000) | C14: Hoja kb_minuta_credencial
A16: Top reglas por frecuencia en minutas: ordena la hoja kb_regla_recomendacion por veces_en_minutas.

Sheet kb_minuta
A1: minuta_id | B1: nombre_cliente | C1: nombre_local | D1: direccion | E1: distrito | F1: fecha_visita | G1: hora | H1: estado_local | I1: antecedentes | J1: tipo_negocio | K1: pisos | L1: cajas | M1: proveedor_internet | N1: tipo_conexion | O1: velocidad_contratada_mbps | P1: bajada_mbps | Q1: subida_mbps | R1: segmento_red | S1: estado_final | T1: asistentes_id | U1: contacto_cliente | V1: requiere_segunda_visita | W1: archivo_pdf | X1: observaciones_carga | Y1: n_respuestas | Z1: n_recomendaciones | AA1: n_acciones
A2: MH-001 | B2: Sicilia | C2: Sicilia – Patio Gastronómico Refugio | D2: Patio Gastronómico Refugio | F2: 45202 | G2: 10:00 | I2: Entrega y configuración de impresoras, creación de tienda y zonas de trabajo en IDPos | J2: RESTAURANTE | S2: SIN_DATO | T2: Kevin Flores, Yomira Mora | U2: Kathy | V2: SI | W2: sicilia.pdf | X2: Dirección exacta no indicada en la minuta. | Y2: =IF(A2="","",COUNTIF(kb_minuta_respuesta!$A$2:$A$2000,A2)) | Z2: =IF(A2="","",COUNTIFS(kb_minuta_recomendacion!$A$2:$A$2000,A2,kb_minuta_recomendacion!$C$2:$C$2000,"RECOMENDACION")) | AA2: =IF(A2="","",COUNTIF(kb_minuta_recomendacion!$A$2:$A$2000,A2)-Z2)
A3: MH-002 | B3: Don Oscar | C3: Don Oscar | D3: Calle Alcanfores 151, Miraflores 15074 | E3: Miraflores | F3: 45227 | G3: 10:00 | H3: EN_OPERACION | I3: Revisión del sistema de impresión del Raspberry y capacitación sobre creación de cupones | J3: REST_PESCADOS | S3: SIN_DATO | T3: Yomira Mora | U3: Piero | V3: NO | W3: donoscar.pdf | Y3: =IF(A3="","",COUNTIF(kb_minuta_respuesta!$A$2:$A$2000,A3)) | Z3: =IF(A3="","",COUNTIFS(kb_minuta_recomendacion!$A$2:$A$2000,A3,kb_minuta_recomendacion!$C$2:$C$2000,"RECOMENDACION")) | AA3: =IF(A3="","",COUNTIF(kb_minuta_recomendacion!$A$2:$A$2000,A3)-Z3)
A4: MH-003 | B4: Barrio Pesquero | C4: Barrio Pesquero | D4: Av. Gral. Antonio Álvarez de Arenales 1746, Lince 15073 | E4: Lince | F4: 45239 | G4: 16:00 | H4: EN_OPERACION | I4: Los programas de impresión no funcionan hasta que se reinicia el internet | J4: REST_PESCADOS | S4: SIN_DATO | T4: Yomira Mora | U4: Giancarlo Sanguinetti | V4: NO | W4: barrio.pdf | Y4: =IF(A4="","",COUNTIF(kb_minuta_respuesta!$A$2:$A$2000,A4)) | Z4: =IF(A4="","",COUNTIFS(kb_minuta_recomendacion!$A$2:$A$2000,A4,kb_minuta_recomendacion!$C$2:$C$2000,"RECOMENDACION")) | AA4: =IF(A4="","",COUNTIF(kb_minuta_recomendacion!$A$2:$A$2000,A4)-Z4)
A5: MH-004 | B5: Rock & Burgers | C5: Rock & Burgers – Huaral | D5: C. Luis Colán 242, Huaral 15201 | E5: Huaral | F5: 46173 | G5: 16:00 | I5: Evaluación de red para implementar el sistema (inicio 01/06/2026) | J5: FAST_FOOD | K5: 3 | M5: CLARO | N5: FIBRA | P5: 91.5 | Q5: 92.49 | R5: 192.168.100.0/24 | S5: APTO | T5: Yomira Mora | U5: Gianfranco (equipo operativo) | V5: NO | W5: rock.pdf | X5: La minuta trae acceso remoto (AnyDesk): ver hoja kb_minuta_credencial. Tecnología de impresiones: wrapper Windows. | Y5: =IF(A5="","",COUNTIF(kb_minuta_respuesta!$A$2:$A$2000,A5)) | Z5: =IF(A5="","",COUNTIFS(kb_minuta_recomendacion!$A$2:$A$2000,A5,kb_minuta_recomendacion!$C$2:$C$2000,"RECOMENDACION")) | AA5: =IF(A5="","",COUNTIF(kb_minuta_recomendacion!$A$2:$A$2000,A5)-Z5)
A6: MH-005 | B6: Dorcher Bier | C6: Dorcher San Miguel | D6: Dorcher San Miguel | E6: San Miguel | F6: 45030 | G6: 10:30 | H6: EN_OPERACION | I6: Sin conexión a internet y sin impresión de comandas ni comprobantes | J6: RESTOBAR | K6: 2 | L6: 3 | M6: MOVISTAR | P6: 94.01 | Q6: 94.43 | S6: SIN_DATO | T6: Arturo Contreras | U6: Karla Sandoval | W6: Visita_Tecnica_DORCHER_SM_14-04-23.pdf | X6: Dos redes (Claro y Movistar). Ese día los equipos se pasaron a Movistar; velocidad medida tras cambiar el switch. Tipo de negocio inferido (cervecería). | Y6: =IF(A6="","",COUNTIF(kb_minuta_respuesta!$A$2:$A$2000,A6)) | Z6: =IF(A6="","",COUNTIFS(kb_minuta_recomendacion!$A$2:$A$2000,A6,kb_minuta_recomendacion!$C$2:$C$2000,"RECOMENDACION")) | AA6: =IF(A6="","",COUNTIF(kb_minuta_recomendacion!$A$2:$A$2000,A6)-Z6)
A7: MH-006 | B7: Dorcher Bier | C7: Dorcher San Miguel | D7: Dorcher San Miguel | E7: San Miguel | F7: 45073 | G7: 16:00 | H7: EN_OPERACION | I7: Impresoras sin imprimir: el cableado del segundo piso se movió entre las redes Claro y Movistar | J7: RESTOBAR | K7: 2 | L7: 3 | M7: CLARO | P7: 93.37 | Q7: 32.36 | S7: SIN_DATO | T7: Arturo Contreras | W7: VISITA_TECNICA_DORCHER_SM_27-05-23.pdf | X7: Todos los equipos se reconfiguraron en la red Claro. Velocidad de la PC Caja 2 (las otras ~92 Mbps). Contacto del cliente vacío en la minuta. | Y7: =IF(A7="","",COUNTIF(kb_minuta_respuesta!$A$2:$A$2000,A7)) | Z7: =IF(A7="","",COUNTIFS(kb_minuta_recomendacion!$A$2:$A$2000,A7,kb_minuta_recomendacion!$C$2:$C$2000,"RECOMENDACION")) | AA7: =IF(A7="","",COUNTIF(kb_minuta_recomendacion!$A$2:$A$2000,A7)-Z7)
A8: MH-007 | B8: Malala | C8: Malala | D8: Calle Alcanfores 151, Miraflores 15074 | E8: Miraflores | F8: 45230 | G8: 21:00 | H8: POR_INAUGURAR | I8: Local sin internet: el proveedor no había habilitado el servicio | J8: RESTOBAR | K8: 2 | M8: OTRO | N8: NO_TIENE | S8: SIN_DATO | T8: Yomira Mora | U8: Marina | V8: SI | W8: Minuta_Visita_Tecnica_Malala_31-10-23.pdf | X8: Se habilitó internet de respaldo con TP-Link 4G + chip Entel. Proveedor principal no habilitado. Tipo de negocio inferido (makis). Misma dirección que Don Oscar en la minuta. | Y8: =IF(A8="","",COUNTIF(kb_minuta_respuesta!$A$2:$A$2000,A8)) | Z8: =IF(A8="","",COUNTIFS(kb_minuta_recomendacion!$A$2:$A$2000,A8,kb_minuta_recomendacion!$C$2:$C$2000,"RECOMENDACION")) | AA8: =IF(A8="","",COUNTIF(kb_minuta_recomendacion!$A$2:$A$2000,A8)-Z8)
A9: MH-008 | B9: Hotel La Confianza | C9: Hotel La Confianza | D9: Catapalla, Lunahuaná 15727 | E9: Lunahuaná | F9: 45232 | G9: 11:30 | H9: EN_OPERACION | I9: Revisión del sistema de impresión del Raspberry | J9: HOSPEDAJE | M9: OTRO | O9: 20 | P9: 2.73 | S9: SIN_DATO | T9: Yomira Mora, Daphne | U9: Caleb | W9: Minuta_Visita_Tecnica_Hotel_La_Confianza_02-11-23.pdf | X9: Tipo de conexión vacío: es satelital (Hughesnet) y P14 no tiene esa opción. Plan de 20 Mbps con 10 GB; al agotar datos reduce la velocidad (2.73 Mbps medidos). | Y9: =IF(A9="","",COUNTIF(kb_minuta_respuesta!$A$2:$A$2000,A9)) | Z9: =IF(A9="","",COUNTIFS(kb_minuta_recomendacion!$A$2:$A$2000,A9,kb_minuta_recomendacion!$C$2:$C$2000,"RECOMENDACION")) | AA9: =IF(A9="","",COUNTIF(kb_minuta_recomendacion!$A$2:$A$2000,A9)-Z9)
A10: MH-009 | B10: Rikoton | C10: RKT Banchero | D10: Av. Santa Rosa 468, Urb. Canto Grande, San Juan de Lurigancho | E10: San Juan de Lurigancho | F10: 45819 | G10: 12:00 | I10: Validar que los equipos estén operativos antes de la implementación | J10: POLLERIA | M10: MOVISTAR | N10: FIBRA | P10: 493.11 | R10: 192.168.0.0/24 | S10: SIN_DATO | T10: Sera G., Yomira Mora | U10: Fernando | W10: RKT_BANCHERO_-_Minuta_Visita.pdf | X10: Dos segmentos de red. Tipo de negocio inferido (pollería/brasas). | Y10: =IF(A10="","",COUNTIF(kb_minuta_respuesta!$A$2:$A$2000,A10)) | Z10: =IF(A10="","",COUNTIFS(kb_minuta_recomendacion!$A$2:$A$2000,A10,kb_minuta_recomendacion!$C$2:$C$2000,"RECOMENDACION")) | AA10: =IF(A10="","",COUNTIF(kb_minuta_recomendacion!$A$2:$A$2000,A10)-Z10)
A11: MH-010 | B11: Rikoton | C11: RKT Bayóvar | D11: Cal. Segunda Zona de Bayóvar Mz. 2 Lt. 1, San Juan de Lurigancho | E11: San Juan de Lurigancho | F11: 45819 | G11: 12:00 | I11: Validar que los equipos estén operativos antes de la implementación | J11: POLLERIA | M11: MOVISTAR | P11: 93.17 | R11: 192.168.1.0/24 | S11: SIN_DATO | T11: Sera G., Yomira Mora | U11: Fernando | W11: RKT_BAYOVAR_-_Minuta_Visita.pdf | X11: Dos segmentos de red. | Y11: =IF(A11="","",COUNTIF(kb_minuta_respuesta!$A$2:$A$2000,A11)) | Z11: =IF(A11="","",COUNTIFS(kb_minuta_recomendacion!$A$2:$A$2000,A11,kb_minuta_recomendacion!$C$2:$C$2000,"RECOMENDACION")) | AA11: =IF(A11="","",COUNTIF(kb_minuta_recomendacion!$A$2:$A$2000,A11)-Z11)
A12: MH-011 | B12: Rikoton | C12: RKT Calle 8 | D12: Av. Los Pinos Mz. S Lt. 3, Campoy II Etapa, San Juan de Lurigancho | E12: San Juan de Lurigancho | F12: 45819 | G12: 12:00 | I12: Validar que los equipos estén operativos antes de la implementación | J12: POLLERIA | K12: 2 | M12: OTRO | P12: 480.02 | Q12: 488.33 | R12: 192.168.1.0/24 | S12: SIN_DATO | T12: Sera G., Yomira Mora | U12: Fernando | W12: RKT_Calle_8-_Minuta_Visita.pdf | X12: Proveedor del speedtest: Yachay Telecomunicaciones. | Y12: =IF(A12="","",COUNTIF(kb_minuta_respuesta!$A$2:$A$2000,A12)) | Z12: =IF(A12="","",COUNTIFS(kb_minuta_recomendacion!$A$2:$A$2000,A12,kb_minuta_recomendacion!$C$2:$C$2000,"RECOMENDACION")) | AA12: =IF(A12="","",COUNTIF(kb_minuta_recomendacion!$A$2:$A$2000,A12)-Z12)
A13: MH-012 | B13: Rikoton | C13: RKT Hacienda | D13: Av. Próceres de la Independencia 1730, Urb. Las Flores de Primavera, San Juan de Lurigancho | E13: San Juan de Lurigancho | F13: 45819 | G13: 12:00 | I13: Validar que los equipos estén operativos antes de la implementación | J13: POLLERIA | M13: MOVISTAR | P13: 88.94 | Q13: 92.64 | S13: APTO | T13: Sera G., Yomira Mora | U13: Fernando | W13: RKT_HACIENDA_-_Minuta_Visita_1.pdf | X13: ID de AnyDesk: ver hoja kb_minuta_credencial. Estado: 'se validaron los equipos y la funcionalidad óptima para la implementación'. | Y13: =IF(A13="","",COUNTIF(kb_minuta_respuesta!$A$2:$A$2000,A13)) | Z13: =IF(A13="","",COUNTIFS(kb_minuta_recomendacion!$A$2:$A$2000,A13,kb_minuta_recomendacion!$C$2:$C$2000,"RECOMENDACION")) | AA13: =IF(A13="","",COUNTIF(kb_minuta_recomendacion!$A$2:$A$2000,A13)-Z13)
A14: MH-013 | B14: Rikoton | C14: RKT Mariscal | D14: Jr. Somos Libres Mz. D Lt. 3, A.H. Somos Libres, San Juan de Lurigancho | E14: San Juan de Lurigancho | F14: 45819 | G14: 12:00 | I14: Validar que los equipos estén operativos antes de la implementación | J14: POLLERIA | K14: 3 | M14: OTRO | N14: FIBRA | P14: 93.91 | Q14: 94.27 | R14: 192.168.1.0/24 | S14: SIN_DATO | T14: Sera G., Yomira Mora | U14: Fernando | W14: RKT_MARISCAL_-_Minuta_Visita_1.pdf | X14: Proveedor del speedtest: Yachay Telecomunicaciones. | Y14: =IF(A14="","",COUNTIF(kb_minuta_respuesta!$A$2:$A$2000,A14)) | Z14: =IF(A14="","",COUNTIFS(kb_minuta_recomendacion!$A$2:$A$2000,A14,kb_minuta_recomendacion!$C$2:$C$2000,"RECOMENDACION")) | AA14: =IF(A14="","",COUNTIF(kb_minuta_recomendacion!$A$2:$A$2000,A14)-Z14)
A15: MH-014 | B15: Rikoton | C15: RKT Villa Flores | D15: Av. Santa Rosa de Lima Mz. T3 Lt. 33, San Juan de Lurigancho | E15: San Juan de Lurigancho | F15: 45819 | G15: 12:00 | I15: Validar que los equipos estén operativos antes de la implementación | J15: POLLERIA | M15: OTRO | P15: 400.19 | R15: 192.168.1.0/24 | S15: SIN_DATO | T15: Sera G., Yomira Mora | U15: Fernando | W15: RKT_Villa_Flores-_Minuta_Visita.pdf | X15: Proveedor WOW. Dos segmentos de red. Router sin puertos libres. | Y15: =IF(A15="","",COUNTIF(kb_minuta_respuesta!$A$2:$A$2000,A15)) | Z15: =IF(A15="","",COUNTIFS(kb_minuta_recomendacion!$A$2:$A$2000,A15,kb_minuta_recomendacion!$C$2:$C$2000,"RECOMENDACION")) | AA15: =IF(A15="","",COUNTIF(kb_minuta_recomendacion!$A$2:$A$2000,A15)-Z15)
A16: MH-015 | B16: Rikoton | C16: RKT Zárate | D16: Av. Chimú 1599, Urb. Zárate, San Juan de Lurigancho | E16: San Juan de Lurigancho | F16: 45819 | G16: 12:00 | I16: Validar que los equipos estén operativos antes de la implementación | J16: POLLERIA | K16: 2 | M16: OTRO | P16: 492.71 | Q16: 404.81 | R16: 192.168.18.0/24 | S16: SIN_DATO | T16: Sera G., Yomira Mora | U16: Fernando | W16: RKT_ZARATE_-_Minuta_Visita.pdf | X16: Proveedor del speedtest: Yachay Telecomunicaciones. Gateway 192.168.18.1. | Y16: =IF(A16="","",COUNTIF(kb_minuta_respuesta!$A$2:$A$2000,A16)) | Z16: =IF(A16="","",COUNTIFS(kb_minuta_recomendacion!$A$2:$A$2000,A16,kb_minuta_recomendacion!$C$2:$C$2000,"RECOMENDACION")) | AA16: =IF(A16="","",COUNTIF(kb_minuta_recomendacion!$A$2:$A$2000,A16)-Z16)
A17: MH-016 | B17: Gelato Alore | C17: Gelato Alore Miguel Dasso | D17: C.C. Sausalito, C. Miguel Dasso 126, San Isidro 15073 | E17: San Isidro | F17: 45839 | G17: 11:00 | I17: Conocer el local, el estado de la red y los equipos de operación antes de implementar | J17: HELADERIA | M17: MOVISTAR | P17: 155.54 | Q17: 2.52 | R17: 192.168.1.0/24 | S17: SIN_DATO | T17: Kevin | U17: Roxana Sujara | W17: Minuta_Gelato_Alore_M_Dasso.pdf | X17: Heladería. La tablet es la caja principal. Subida muy baja (2.52 Mbps). QR de WiFi: ver hoja kb_minuta_credencial. | Y17: =IF(A17="","",COUNTIF(kb_minuta_respuesta!$A$2:$A$2000,A17)) | Z17: =IF(A17="","",COUNTIFS(kb_minuta_recomendacion!$A$2:$A$2000,A17,kb_minuta_recomendacion!$C$2:$C$2000,"RECOMENDACION")) | AA17: =IF(A17="","",COUNTIF(kb_minuta_recomendacion!$A$2:$A$2000,A17)-Z17)
A18: MH-017 | B18: Gelato Alore | C18: Gelato Alore Ejército | D18: Av. del Ejército 395, Miraflores 15074 | E18: Miraflores | F18: 45839 | G18: 13:15 | I18: Conocer el local, el estado de la red y los equipos de operación antes de implementar | J18: HELADERIA | M18: MOVISTAR | P18: 89.44 | Q18: 89.61 | R18: 192.168.5.0/24 | S18: SIN_DATO | T18: Kevin | U18: Mirella León | W18: Minuta_Gelato_Alore_Ejercito.pdf | X18: Heladería. QR de WiFi: ver hoja kb_minuta_credencial. | Y18: =IF(A18="","",COUNTIF(kb_minuta_respuesta!$A$2:$A$2000,A18)) | Z18: =IF(A18="","",COUNTIFS(kb_minuta_recomendacion!$A$2:$A$2000,A18,kb_minuta_recomendacion!$C$2:$C$2000,"RECOMENDACION")) | AA18: =IF(A18="","",COUNTIF(kb_minuta_recomendacion!$A$2:$A$2000,A18)-Z18)
A19: MH-018 | B19: Gelato Alore | C19: Gelato Alore 2 de Mayo | D19: Av. Dos de Mayo 1186, San Isidro 15073 | E19: San Isidro | F19: 45839 | G19: 15:40 | I19: Conocer el local, el estado de la red y los equipos de operación antes de implementar | J19: HELADERIA | M19: CLARO | P19: 233.24 | Q19: 55.05 | R19: 192.168.0.0/24 | S19: SIN_DATO | T19: Kevin | U19: Blanca Coronel | W19: Minuta_Gelato_Alore_2_de_Mayo.pdf | X19: Heladería. Prueba adicional por WiFi móvil: 89.44 / 89.61 Mbps. QR de WiFi: ver hoja kb_minuta_credencial. | Y19: =IF(A19="","",COUNTIF(kb_minuta_respuesta!$A$2:$A$2000,A19)) | Z19: =IF(A19="","",COUNTIFS(kb_minuta_recomendacion!$A$2:$A$2000,A19,kb_minuta_recomendacion!$C$2:$C$2000,"RECOMENDACION")) | AA19: =IF(A19="","",COUNTIF(kb_minuta_recomendacion!$A$2:$A$2000,A19)-Z19)
A20: MH-019 | B20: ALF Sandwiches | C20: ALF Sandwiches | D20: Nicolás de Piérola 431, Barranco | E20: Barranco | F20: 45586 | G20: 19:00 | J20: FAST_FOOD | L20: 1 | P20: 322.45 | S20: SIN_DATO | T20: Yomira Mora, Brandon Grados | U20: Einar Paulsen | W20: Minuta de Visita Técnica - ALF SANDWICHES.pdf | X20: Ya tiene 1 Sunmi V2 Pro con IDPos. Ventas rápidas en caja: no se consideran las mesas. Router a 12 m de la caja. | Y20: =IF(A20="","",COUNTIF(kb_minuta_respuesta!$A$2:$A$2000,A20)) | Z20: =IF(A20="","",COUNTIFS(kb_minuta_recomendacion!$A$2:$A$2000,A20,kb_minuta_recomendacion!$C$2:$C$2000,"RECOMENDACION")) | AA20: =IF(A20="","",COUNTIF(kb_minuta_recomendacion!$A$2:$A$2000,A20)-Z20)
A21: MH-020 | B21: La Carpita del Sabor | C21: La Carpita del Sabor | D21: Av. San Luis 2656, San Borja 15037 | E21: San Borja | F21: 45665 | G21: 22:00 | J21: RESTAURANTE | K21: 2 | L21: 1 | S21: SIN_DATO | T21: Kevin | U21: Yessenia | W21: Minuta de Visita técnica - La Carpita del Sabor.pdf | X21: Restaurante con barras. Router y switch en caja. Impresoras: caja, cocina, bebidas/postres/vinos (piso 1) y barra piso 2–terraza. Reestructurar el cableado no impide el inicio. El PDF llegó dos veces. | Y21: =IF(A21="","",COUNTIF(kb_minuta_respuesta!$A$2:$A$2000,A21)) | Z21: =IF(A21="","",COUNTIFS(kb_minuta_recomendacion!$A$2:$A$2000,A21,kb_minuta_recomendacion!$C$2:$C$2000,"RECOMENDACION")) | AA21: =IF(A21="","",COUNTIF(kb_minuta_recomendacion!$A$2:$A$2000,A21)-Z21)
A22: MH-021 | B22: Los Juárez | C22: Los Juárez Asia | D22: Boulevard de Asia | E22: Asia | F22: 46021 | G22: 12:30 | H22: POR_INAUGURAR | J22: RESTOBAR | K22: 2 | N22: NO_TIENE | S22: SIN_DATO | T22: Kevin | U22: Jesús Pinto | W22: Minuta de visita técnica - Los Juarez Asia.pdf | X22: Aún sin puntos de red ni servicio de internet, y sin impresoras. Adquirirá Sunmi con Izipay, impresoras y 2 pantallas para caja. | Y22: =IF(A22="","",COUNTIF(kb_minuta_respuesta!$A$2:$A$2000,A22)) | Z22: =IF(A22="","",COUNTIFS(kb_minuta_recomendacion!$A$2:$A$2000,A22,kb_minuta_recomendacion!$C$2:$C$2000,"RECOMENDACION")) | AA22: =IF(A22="","",COUNTIF(kb_minuta_recomendacion!$A$2:$A$2000,A22)-Z22)
A23: MH-022 | B23: Mala Vida | C23: Mala Vida | D23: Calle Tarata 150, Miraflores | E23: Miraflores | F23: 45786 | G23: 11:00 | J23: DISCOTECA_BAR | M23: WIN | S23: SIN_DATO | T23: Kevin, Sera | U23: Eduardo Salas | W23: Minuta de Visita técnica - Mala Vida.docx | X23: Entrega de equipos antes del inicio. Barra 1: 2 Sunmi T2 mini + impresora 3nStar RPT008; Barra 2: 1 Sunmi T2 mini + impresora. La laptop no se queda: viabilizar Raspberry o la PC del DJ. Claves WiFi y usuario de la laptop: ver hoja kb_minuta_credencial. | Y23: =IF(A23="","",COUNTIF(kb_minuta_respuesta!$A$2:$A$2000,A23)) | Z23: =IF(A23="","",COUNTIFS(kb_minuta_recomendacion!$A$2:$A$2000,A23,kb_minuta_recomendacion!$C$2:$C$2000,"RECOMENDACION")) | AA23: =IF(A23="","",COUNTIF(kb_minuta_recomendacion!$A$2:$A$2000,A23)-Z23)
A24: MH-023 | B24: Huambra | C24: Huambra | D24: Miraflores | E24: Miraflores | F24: 45607 | G24: 15:00 | J24: RESTAURANTE | L24: 1 | R24: 192.168.18.x | S24: SIN_DATO | T24: Kevin | U24: Juan Pablo | W24: Minuta de Visita Técnica Huambra.docx | X24: Instalación: Raspberry en caja; impresoras caja, barra, cocina y empaquetados en el mismo segmento; pantallas Sunmi D2 mini en patio y salón principal. | Y24: =IF(A24="","",COUNTIF(kb_minuta_respuesta!$A$2:$A$2000,A24)) | Z24: =IF(A24="","",COUNTIFS(kb_minuta_recomendacion!$A$2:$A$2000,A24,kb_minuta_recomendacion!$C$2:$C$2000,"RECOMENDACION")) | AA24: =IF(A24="","",COUNTIF(kb_minuta_recomendacion!$A$2:$A$2000,A24)-Z24)
A25: MH-024 | B25: Saltao | C25: Saltao Larcomar | D25: Sótano 3 Larcomar (patio de comidas) | E25: Miraflores | F25: 45332 | G25: 11:00 | J25: FAST_FOOD | L25: 1 | M25: ENTEL | N25: CHIP | R25: 192.168.0.x | S25: SIN_DATO | T25: Kevin Flores | U25: Vanessa Chinen, Sharon Rabanal | W25: Minuta Instalación Técnica Saltao Larcomar.docx | X25: Patio de comidas: TP-Link con chip Entel. Sin puntos de red; la cobertura WiFi no llega al 100 %: TP-Link en el punto más alto con canaleta y extensión. Clave del TP-Link, red WiFi y puerto del Raspberry: ver hoja kb_minuta_credencial. Ubicación (Larcomar o El Refugio) por confirmar con el equipo. | Y25: =IF(A25="","",COUNTIF(kb_minuta_respuesta!$A$2:$A$2000,A25)) | Z25: =IF(A25="","",COUNTIFS(kb_minuta_recomendacion!$A$2:$A$2000,A25,kb_minuta_recomendacion!$C$2:$C$2000,"RECOMENDACION")) | AA25: =IF(A25="","",COUNTIF(kb_minuta_recomendacion!$A$2:$A$2000,A25)-Z25)
A26: MH-025 | B26: Maki Sam | C26: Maki Sam Real Plaza | D26: Real Plaza Trujillo | E26: Trujillo | F26: 45580 | G26: 10:00 | J26: REST_ORIENTAL | L26: 1 | N26: FIBRA | R26: 192.168.1.x | S26: SIN_DATO | T26: Kimberly Huamani | U26: Vanessa | W26: Minuta Técnica Maki Sam Real plaza.docx | X26: Tercer local, en patio de comidas. 4 impresoras Bienex (caja, barra sushi, bar, cocina) pasadas al mismo segmento con cable USB; laptop propia del local. ID de AnyDesk: ver hoja kb_minuta_credencial. | Y26: =IF(A26="","",COUNTIF(kb_minuta_respuesta!$A$2:$A$2000,A26)) | Z26: =IF(A26="","",COUNTIFS(kb_minuta_recomendacion!$A$2:$A$2000,A26,kb_minuta_recomendacion!$C$2:$C$2000,"RECOMENDACION")) | AA26: =IF(A26="","",COUNTIF(kb_minuta_recomendacion!$A$2:$A$2000,A26)-Z26)
A27: MH-026 | B27: Maki Sam | C27: Maki Sam Primavera | D27: Maki Sam sede centro | F27: 45580 | H27: EN_OPERACION | I27: La impresora de caja se conecta y desconecta: la entrada del cable de red está floja | J27: REST_ORIENTAL | L27: 1 | S27: SIN_DATO | T27: Kimberly Huamani | U27: Kelly Sayan | W27: Minuta Técnica makisamprimavera.docx | X27: Minuta corta: solo antecedentes. | Y27: =IF(A27="","",COUNTIF(kb_minuta_respuesta!$A$2:$A$2000,A27)) | Z27: =IF(A27="","",COUNTIFS(kb_minuta_recomendacion!$A$2:$A$2000,A27,kb_minuta_recomendacion!$C$2:$C$2000,"RECOMENDACION")) | AA27: =IF(A27="","",COUNTIF(kb_minuta_recomendacion!$A$2:$A$2000,A27)-Z27)
A28: MH-027 | B28: Gourmety | C28: Gourmety | D28: Av. Rivera Navarrete 575, San Isidro | E28: San Isidro | F28: 45727 | G28: 12:30 | H28: EN_OBRA | J28: CAFETERIA | K28: 2 | L28: 1 | S28: SIN_DATO | T28: Fabián Guadiamos, Sera Ghafari | U28: Joanna | W28: Minuta Visita Técnica - Gourmety 11.03.22 (1).docx | X28: Local en obra: puntos de red y de corriente se instalan del 16 al 22/03. El nombre del archivo dice 11.03.22, pero la fecha es 2025. | Y28: =IF(A28="","",COUNTIF(kb_minuta_respuesta!$A$2:$A$2000,A28)) | Z28: =IF(A28="","",COUNTIFS(kb_minuta_recomendacion!$A$2:$A$2000,A28,kb_minuta_recomendacion!$C$2:$C$2000,"RECOMENDACION")) | AA28: =IF(A28="","",COUNTIF(kb_minuta_recomendacion!$A$2:$A$2000,A28)-Z28)
A29: MH-028 | B29: Bros | C29: Bros – Refugio Gastronómico | D29: Refugio Gastronómico | E29: Santiago de Surco | F29: 45372 | G29: 13:00 | J29: FAST_FOOD | L29: 1 | P29: 94.42 | S29: SIN_DATO | T29: Nelson Luque | U29: Vanessa, Elio | W29: Minuta Visita Técnica bros.docx | X29: Patio gastronómico. Laptop conectada directo al router. Las minutas de Juicy Lucy – Larco (y V2) tienen este mismo texto: no se cargaron. | Y29: =IF(A29="","",COUNTIF(kb_minuta_respuesta!$A$2:$A$2000,A29)) | Z29: =IF(A29="","",COUNTIFS(kb_minuta_recomendacion!$A$2:$A$2000,A29,kb_minuta_recomendacion!$C$2:$C$2000,"RECOMENDACION")) | AA29: =IF(A29="","",COUNTIF(kb_minuta_recomendacion!$A$2:$A$2000,A29)-Z29)
A30: MH-029 | B30: El Chito | C30: El Chito | F30: 45210 | G30: 16:00 | J30: REST_PESCADOS | L30: 1 | M30: MOVISTAR | N30: FIBRA | O30: 1000 | S30: SIN_DATO | T30: Kevin Flores | U30: Leonardo, Rosbeyli | W30: Minuta Visita Técnica El Chito.docx | X30: El cableado y los puntos de red se estaban instalando ese día. Impresoras: cocina y caja-barra. | Y30: =IF(A30="","",COUNTIF(kb_minuta_respuesta!$A$2:$A$2000,A30)) | Z30: =IF(A30="","",COUNTIFS(kb_minuta_recomendacion!$A$2:$A$2000,A30,kb_minuta_recomendacion!$C$2:$C$2000,"RECOMENDACION")) | AA30: =IF(A30="","",COUNTIF(kb_minuta_recomendacion!$A$2:$A$2000,A30)-Z30)
A31: MH-030 | B31: Shimaya Ramen | C31: Shimaya Comas | D31: Av. Los Ángeles 602, local FC-3041, 3er nivel | E31: Comas | F31: 45360 | G31: 11:00 | J31: REST_ORIENTAL | L31: 1 | M31: WIN | N31: FIBRA | R31: 192.168.100.x | S31: SIN_DATO | T31: Kevin | U31: Yanina | W31: Visita Técnica Shimaya - Comas.docx | X31: Impresoras caja, ramen, salteados, frituras y makis por cable; 2 cables de cámaras en el mismo switch y cables de cámara sueltos. Clave WiFi: ver hoja kb_minuta_credencial. | Y31: =IF(A31="","",COUNTIF(kb_minuta_respuesta!$A$2:$A$2000,A31)) | Z31: =IF(A31="","",COUNTIFS(kb_minuta_recomendacion!$A$2:$A$2000,A31,kb_minuta_recomendacion!$C$2:$C$2000,"RECOMENDACION")) | AA31: =IF(A31="","",COUNTIF(kb_minuta_recomendacion!$A$2:$A$2000,A31)-Z31)
A32: MH-031 | B32: Shimaya Ramen | C32: Shimaya La Molina | D32: Av. Flora Tristán 471, La Molina 15024 | E32: La Molina | F32: 45366 | G32: 11:00 | J32: REST_ORIENTAL | L32: 1 | M32: CLARO | N32: COAXIAL | O32: 100 | S32: SIN_DATO | T32: Kevin | W32: Minuta visita Técnica Shimaya Ramen - La Molina.docx | X32: Claro HFC. Switch principal 10/100 con cámaras, PC de caja e impresora. 3 access points (barra makis, salón zona B, entrada). WiFi libre para clientes. Caja USB con la PC. Tablets de mozos. Clave WiFi: ver hoja kb_minuta_credencial. | Y32: =IF(A32="","",COUNTIF(kb_minuta_respuesta!$A$2:$A$2000,A32)) | Z32: =IF(A32="","",COUNTIFS(kb_minuta_recomendacion!$A$2:$A$2000,A32,kb_minuta_recomendacion!$C$2:$C$2000,"RECOMENDACION")) | AA32: =IF(A32="","",COUNTIF(kb_minuta_recomendacion!$A$2:$A$2000,A32)-Z32)
A33: MH-032 | B33: Shimaya Ramen | C33: Shimaya Kennedy (Miraflores) | D33: Av. Diagonal 344, Miraflores | E33: Miraflores | F33: 45364 | G33: 16:00 | J33: REST_ORIENTAL | L33: 1 | M33: MOVISTAR | O33: 100 | S33: SIN_DATO | T33: Kevin Flores | U33: Gabriela | W33: Minuta Visita Técnica Shimaya Ramen-Miraflores.docx | X33: Switch 10/100 TP-Link con cámaras, PC de caja e impresoras. Caja USB. Frituras: punto de red por cambiar; Makis: RJ45 por cambiar. Tablets por WiFi. | Y33: =IF(A33="","",COUNTIF(kb_minuta_respuesta!$A$2:$A$2000,A33)) | Z33: =IF(A33="","",COUNTIFS(kb_minuta_recomendacion!$A$2:$A$2000,A33,kb_minuta_recomendacion!$C$2:$C$2000,"RECOMENDACION")) | AA33: =IF(A33="","",COUNTIF(kb_minuta_recomendacion!$A$2:$A$2000,A33)-Z33)
A34: MH-033 | B34: Modonese | C34: Modonese Arica | D34: Jr. Arica 880 | F34: 45605 | H34: EN_OPERACION | I34: El local reportaba lentitud de red | J34: REST_PESCADOS | L34: 1 | N34: FIBRA | O34: 400 | S34: SIN_DATO | T34: Kevin | U34: Diego (caja) | V34: SI | W34: Minuta Visita Técnica Modonese Arica.docx | X34: Red estable en la visita. Tablet de caja por WiFi (−37 dBm, estable). Cable de cámaras junto a corriente y bajo un equipo con motor: ruido hasta el router. Se cambió el cable Cat5e por Cat6a hacia el Raspberry. | Y34: =IF(A34="","",COUNTIF(kb_minuta_respuesta!$A$2:$A$2000,A34)) | Z34: =IF(A34="","",COUNTIFS(kb_minuta_recomendacion!$A$2:$A$2000,A34,kb_minuta_recomendacion!$C$2:$C$2000,"RECOMENDACION")) | AA34: =IF(A34="","",COUNTIF(kb_minuta_recomendacion!$A$2:$A$2000,A34)-Z34)
A35: MH-034 | B35: Omakase | C35: Omakase | D35: Santiago de Compostela, La Molina 15026 | E35: La Molina | F35: 45243 | G35: 15:00 | J35: REST_ORIENTAL | L35: 1 | S35: SIN_DATO | T35: Sandra | U35: Keyri, Álvaro | W35: Minuta Visita Técnica OMAKASE.docx | X35: Sin acceso al cuarto de telecomunicaciones: solo test por WiFi. Trabajan desde un celular por WiFi; posible laptop temporal. La barra principal no tiene punto de red. El cliente no desea el Raspberry. | Y35: =IF(A35="","",COUNTIF(kb_minuta_respuesta!$A$2:$A$2000,A35)) | Z35: =IF(A35="","",COUNTIFS(kb_minuta_recomendacion!$A$2:$A$2000,A35,kb_minuta_recomendacion!$C$2:$C$2000,"RECOMENDACION")) | AA35: =IF(A35="","",COUNTIF(kb_minuta_recomendacion!$A$2:$A$2000,A35)-Z35)
A36: MH-035 | B36: Shimaya Ramen | C36: Shimaya Chorrillos | D36: Av. Defensores del Morro 448, Chorrillos | E36: Chorrillos | F36: 45363 | G36: 11:00 | J36: REST_ORIENTAL | L36: 1 | M36: MOVISTAR | N36: COAXIAL | O36: 250 | S36: SIN_DATO | T36: Kevin | U36: Shinjuu | W36: Minuta de Visita tecnica Shimaya chorrillos .docx | X36: Movistar HFC. Switch TP-Link 10/100. Puntos de red: PC de caja e impresoras caja, makis, frituras, ramen, salteados y pre-cuentas. Tablets. Clave WiFi: ver hoja kb_minuta_credencial. | Y36: =IF(A36="","",COUNTIF(kb_minuta_respuesta!$A$2:$A$2000,A36)) | Z36: =IF(A36="","",COUNTIFS(kb_minuta_recomendacion!$A$2:$A$2000,A36,kb_minuta_recomendacion!$C$2:$C$2000,"RECOMENDACION")) | AA36: =IF(A36="","",COUNTIF(kb_minuta_recomendacion!$A$2:$A$2000,A36)-Z36)
A37: MH-036 | B37: Shimaya Ramen | C37: Shimaya Los Olivos | D37: Av. Carlos Izaguirre 789 | E37: Los Olivos | F37: 45360 | G37: 16:00 | J37: REST_ORIENTAL | L37: 1 | M37: WIN | N37: FIBRA | O37: 400 | R37: 192.168.18.x | S37: SIN_DATO | T37: Kevin | U37: Yrama | W37: Minuta visita Técnica Shimaya Los Olivos.docx | X37: La impresora de caja (de red) pierde conexión por cable mal ponchado (norma A, cruzado). RJ45 de makis por cambiar. Switch de 8 puertos 10/100. | Y37: =IF(A37="","",COUNTIF(kb_minuta_respuesta!$A$2:$A$2000,A37)) | Z37: =IF(A37="","",COUNTIFS(kb_minuta_recomendacion!$A$2:$A$2000,A37,kb_minuta_recomendacion!$C$2:$C$2000,"RECOMENDACION")) | AA37: =IF(A37="","",COUNTIF(kb_minuta_recomendacion!$A$2:$A$2000,A37)-Z37)
A38: MH-037 | B38: Shimaya Ramen | C38: Shimaya SJL | D38: Av. Lurigancho 997-999, tienda B-3006, Urb. Zárate Industrial | E38: San Juan de Lurigancho | F38: 45367 | G38: 11:00 | J38: REST_ORIENTAL | L38: 1 | M38: WIN | O38: 400 | S38: SIN_DATO | T38: Kevin | U38: Alvani | W38: Minuta visita Técnica Shimaya Ramen - SJL.docx | X38: Switch con PC de caja, cámaras e impresoras. Caja USB con la PC. 5 tablets de mozos. | Y38: =IF(A38="","",COUNTIF(kb_minuta_respuesta!$A$2:$A$2000,A38)) | Z38: =IF(A38="","",COUNTIFS(kb_minuta_recomendacion!$A$2:$A$2000,A38,kb_minuta_recomendacion!$C$2:$C$2000,"RECOMENDACION")) | AA38: =IF(A38="","",COUNTIF(kb_minuta_recomendacion!$A$2:$A$2000,A38)-Z38)
A39: MH-038 | B39: Shimaya Ramen | C39: Shimaya San Borja | D39: Av. Aviación 3341, San Borja | E39: San Borja | F39: 45365 | G39: 11:00 | J39: REST_ORIENTAL | L39: 1 | M39: MOVISTAR | N39: FIBRA | P39: 350 | S39: SIN_DATO | T39: Kevin | U39: Daya | W39: Minuta Visita Técnica Shimaya Ramen-San Borja.docx | X39: Velocidad medida en la laptop de ID. Switch 10/100 TP-Link con cámaras, PC de caja e impresoras. Caja USB. RJ45 de frituras por cambiar. 5 tablets Lenovo. | Y39: =IF(A39="","",COUNTIF(kb_minuta_respuesta!$A$2:$A$2000,A39)) | Z39: =IF(A39="","",COUNTIFS(kb_minuta_recomendacion!$A$2:$A$2000,A39,kb_minuta_recomendacion!$C$2:$C$2000,"RECOMENDACION")) | AA39: =IF(A39="","",COUNTIF(kb_minuta_recomendacion!$A$2:$A$2000,A39)-Z39)
A40: MH-039 | B40: Caleta | C40: Caleta de la Punta – Callao | D40: Malecón Pardo 180, La Punta 07021 | E40: La Punta | F40: 45783 | G40: 09:00 | J40: REST_PESCADOS | L40: 2 | M40: WIN | O40: 100 | S40: SIN_DATO | T40: Kevin | U40: Briggitte, Andrea | W40: Minuta de Visita técnica - Caleta Callao.docx | X40: Dos lugares de preparación (Caleta 01 y 02), cada uno con su PC e impresora 3nStar RPT006B. 2 tablets Samsung. Claves WiFi: ver hoja kb_minuta_credencial. | Y40: =IF(A40="","",COUNTIF(kb_minuta_respuesta!$A$2:$A$2000,A40)) | Z40: =IF(A40="","",COUNTIFS(kb_minuta_recomendacion!$A$2:$A$2000,A40,kb_minuta_recomendacion!$C$2:$C$2000,"RECOMENDACION")) | AA40: =IF(A40="","",COUNTIF(kb_minuta_recomendacion!$A$2:$A$2000,A40)-Z40)
...

Sheet kb_minuta_respuesta
A1: minuta_id | B1: pregunta_id | C1: alcance | D1: valor | E1: confianza | F1: fuente_en_minuta | G1: texto_pregunta
A2: MH-001 | B2: P01 | D2: Sicilia | E2: EXPLICITO | F2: Título de la minuta | G2: =IF(B2="","",IFERROR(INDEX(ref_preguntas!$C$2:$C$200,MATCH(B2,ref_preguntas!$A$2:$A$200,0)),"ID no existe"))
A3: MH-001 | B3: P03 | D3: Patio Gastronómico Refugio | E3: EXPLICITO | F3: Lugar | G3: =IF(B3="","",IFERROR(INDEX(ref_preguntas!$C$2:$C$200,MATCH(B3,ref_preguntas!$A$2:$A$200,0)),"ID no existe"))
A4: MH-001 | B4: P04 | D4: Kathy | E4: EXPLICITO | F4: Team cliente | G4: =IF(B4="","",IFERROR(INDEX(ref_preguntas!$C$2:$C$200,MATCH(B4,ref_preguntas!$A$2:$A$200,0)),"ID no existe"))
A5: MH-001 | B5: P06 | D5: 2023-10-03 | E5: EXPLICITO | F5: Fecha y hora | G5: =IF(B5="","",IFERROR(INDEX(ref_preguntas!$C$2:$C$200,MATCH(B5,ref_preguntas!$A$2:$A$200,0)),"ID no existe"))
A6: MH-001 | B6: P11 | D6: COCINA, TERRAZA | E6: INFERIDO | F6: Recomendaciones mencionan cocina y terraza | G6: =IF(B6="","",IFERROR(INDEX(ref_preguntas!$C$2:$C$200,MATCH(B6,ref_preguntas!$A$2:$A$200,0)),"ID no existe"))
A7: MH-001 | B7: P38 | D7: NO | E7: INFERIDO | F7: La impresora de cocina está lejos del punto de red | G7: =IF(B7="","",IFERROR(INDEX(ref_preguntas!$C$2:$C$200,MATCH(B7,ref_preguntas!$A$2:$A$200,0)),"ID no existe"))
A8: MH-001 | B8: P50 | D8: SI | E8: EXPLICITO | F8: Siguientes acciones | G8: =IF(B8="","",IFERROR(INDEX(ref_preguntas!$C$2:$C$200,MATCH(B8,ref_preguntas!$A$2:$A$200,0)),"ID no existe"))
A9: MH-001 | B9: P50a | D9: Conexión de impresoras | E9: EXPLICITO | F9: Siguientes acciones | G9: =IF(B9="","",IFERROR(INDEX(ref_preguntas!$C$2:$C$200,MATCH(B9,ref_preguntas!$A$2:$A$200,0)),"ID no existe"))
A10: MH-001 | B10: P51 | D10: ID: Kevin Flores, Yomira Mora · Cliente: Kathy | E10: EXPLICITO | F10: Asistentes | G10: =IF(B10="","",IFERROR(INDEX(ref_preguntas!$C$2:$C$200,MATCH(B10,ref_preguntas!$A$2:$A$200,0)),"ID no existe"))
A11: MH-001 | B11: P12a | D11: SI | E11: INFERIDO | F11: Impresoras en áreas, incluida cocina | G11: =IF(B11="","",IFERROR(INDEX(ref_preguntas!$C$2:$C$200,MATCH(B11,ref_preguntas!$A$2:$A$200,0)),"ID no existe"))
A12: MH-001 | B12: P09 | D12: RESTAURANTE | E12: EXPLICITO | F12: Rubro confirmado por el equipo (2026-10-10) | G12: =IF(B12="","",IFERROR(INDEX(ref_preguntas!$C$2:$C$200,MATCH(B12,ref_preguntas!$A$2:$A$200,0)),"ID no existe"))
A13: MH-002 | B13: P01 | D13: Don Oscar | E13: EXPLICITO | F13: Título de la minuta | G13: =IF(B13="","",IFERROR(INDEX(ref_preguntas!$C$2:$C$200,MATCH(B13,ref_preguntas!$A$2:$A$200,0)),"ID no existe"))
... A27: MH-003 | B27: P11 | D27: BAR, CAJA | E27: INFERIDO | F27: Recomendación: switch en barra para impresora de barra y caja | G27: =IF(B27="","",IFERROR(INDEX(ref_preguntas!$C$2:$C$200,MATCH(B27,ref_preguntas!$A$2:$A$200,0)),"ID no existe"))
A28: MH-003 | B28: P22 | C28: L_CAJAS:1 | D28: SI | E28: INFERIDO | F28: PC con programas de impresión | G28: =IF(B28="","",IFERROR(INDEX(ref_preguntas!$C$2:$C$200,MATCH(B28,ref_preguntas!$A$2:$A$200,0)),"ID no existe"))
A29: MH-003 | B29: P23 | C29: L_CAJAS:1 | D29: WIFI | E29: EXPLICITO | F29: Desarrollo | G29: =IF(B29="","",IFERROR(INDEX(ref_preguntas!$C$2:$C$200,MATCH(B29,ref_preguntas!$A$2:$A$200,0)),"ID no existe"))
A30: MH-003 | B30: P40 | D30: DESORDENADO | E30: EXPLICITO | F30: Desarrollo | G30: =IF(B30="","",IFERROR(INDEX(ref_preguntas!$C$2:$C$200,MATCH(B30,ref_preguntas!$A$2:$A$200,0)),"ID no existe"))
A31: MH-003 | B31: P45 | D31: SI | E31: EXPLICITO | F31: Desarrollo: repetidores | G31: =IF(B31="","",IFERROR(INDEX(ref_preguntas!$C$2:$C$200,MATCH(B31,ref_preguntas!$A$2:$A$200,0)),"ID no existe"))
A32: MH-003 | B32: P51 | D32: ID: Yomira Mora · Cliente: Giancarlo Sanguinetti | E32: EXPLICITO | F32: Asistentes | G32: =IF(B32="","",IFERROR(INDEX(ref_preguntas!$C$2:$C$200,MATCH(B32,ref_preguntas!$A$2:$A$200,0)),"ID no existe"))
A33: MH-003 | B33: P12a | D33: SI | E33: INFERIDO | F33: Impresora de barra | G33: =IF(B33="","",IFERROR(INDEX(ref_preguntas!$C$2:$C$200,MATCH(B33,ref_preguntas!$A$2:$A$200,0)),"ID no existe"))
A34: MH-003 | B34: P09 | D34: REST_PESCADOS | E34: EXPLICITO | F34: Rubro confirmado por el equipo (2026-10-10) | G34: =IF(B34="","",IFERROR(INDEX(ref_preguntas!$C$2:$C$200,MATCH(B34,ref_preguntas!$A$2:$A$200,0)),"ID no existe"))
A35: MH-004 | B35: P01 | D35: Rock & Burgers | E35: EXPLICITO | F35: Título de la minuta | G35: =IF(B35="","",IFERROR(INDEX(ref_preguntas!$C$2:$C$200,MATCH(B35,ref_preguntas!$A$2:$A$200,0)),"ID no existe"))
A36: MH-004 | B36: P03 | D36: C. Luis Colán 242, Huaral 15201 | E36: EXPLICITO | F36: Dirección | G36: =IF(B36="","",IFERROR(INDEX(ref_preguntas!$C$2:$C$200,MATCH(B36,ref_preguntas!$A$2:$A$200,0)),"ID no existe"))
A37: MH-004 | B37: P04 | D37: Gianfranco (equipo operativo) | E37: EXPLICITO | F37: Team cliente | G37: =IF(B37="","",IFERROR(INDEX(ref_preguntas!$C$2:$C$200,MATCH(B37,ref_preguntas!$A$2:$A$200,0)),"ID no existe"))
A38: MH-004 | B38: P06 | D38: 2026-05-31 | E38: EXPLICITO | F38: Fecha y hora | G38: =IF(B38="","",IFERROR(INDEX(ref_preguntas!$C$2:$C$200,MATCH(B38,ref_preguntas!$A$2:$A$200,0)),"ID no existe"))
A39: MH-004 | B39: P10 | D39: 3 | E39: EXPLICITO | F39: Pisos | G39: =IF(B39="","",IFERROR(INDEX(ref_preguntas!$C$2:$C$200,MATCH(B39,ref_preguntas!$A$2:$A$200,0)),"ID no existe"))
A40: MH-004 | B40: P11 | D40: CAJA, COCINA, SALON_1, SALON_2 | E40: INFERIDO | F40: Salones en piso 2 y 3, caja y cocina | G40: =IF(B40="","",IFERROR(INDEX(ref_preguntas!$C$2:$C$200,MATCH(B40,ref_preguntas!$A$2:$A$200,0)),"ID no existe"))
A41: MH-004 | B41: P13 | D41: CLARO | E41: EXPLICITO | F41: Proveedor | G41: =IF(B41="","",IFERROR(INDEX(ref_preguntas!$C$2:$C$200,MATCH(B41,ref_preguntas!$A$2:$A$200,0)),"ID no existe"))
... A43: MH-004 | B43: P18 | D43: CAJA | E43: EXPLICITO | F43: Caja y router principal | G43: =IF(B43="","",IFERROR(INDEX(ref_preguntas!$C$2:$C$200,MATCH(B43,ref_preguntas!$A$2:$A$200,0)),"ID no existe"))
A44: MH-004 | B44: P22 | C44: L_CAJAS:1 | D44: SI | E44: EXPLICITO | F44: Equipos tecnológicos (PC de caja) | G44: =IF(B44="","",IFERROR(INDEX(ref_preguntas!$C$2:$C$200,MATCH(B44,ref_preguntas!$A$2:$A$200,0)),"ID no existe"))
A45: MH-004 | B45: P23 | C45: L_CAJAS:1 | D45: WIFI | E45: EXPLICITO | F45: Equipos tecnológicos | G45: =IF(B45="","",IFERROR(INDEX(ref_preguntas!$C$2:$C$200,MATCH(B45,ref_preguntas!$A$2:$A$200,0)),"ID no existe"))
A46: MH-004 | B46: P26 | D46: 2 | E46: EXPLICITO | F46: Impresoras | G46: =IF(B46="","",IFERROR(INDEX(ref_preguntas!$C$2:$C$200,MATCH(B46,ref_preguntas!$A$2:$A$200,0)),"ID no existe"))
A47: MH-004 | B47: P27 | C47: L_IMPRESORAS:1 | D47: CAJA | E47: EXPLICITO | F47: Impresora de caja (bebidas se preparan en caja) | G47: =IF(B47="","",IFERROR(INDEX(ref_preguntas!$C$2:$C$200,MATCH(B47,ref_preguntas!$A$2:$A$200,0)),"ID no existe"))
A48: MH-004 | B48: P30 | C48: L_IMPRESORAS:1 | D48: USB | E48: EXPLICITO | F48: Especificaciones de impresoras | G48: =IF(B48="","",IFERROR(INDEX(ref_preguntas!$C$2:$C$200,MATCH(B48,ref_preguntas!$A$2:$A$200,0)),"ID no existe"))
A49: MH-004 | B49: P27 | C49: L_IMPRESORAS:2 | D49: COCINA | E49: EXPLICITO | F49: Especificaciones de impresoras | G49: =IF(B49="","",IFERROR(INDEX(ref_preguntas!$C$2:$C$200,MATCH(B49,ref_preguntas!$A$2:$A$200,0)),"ID no existe"))
A50: MH-004 | B50: P29 | C50: L_IMPRESORAS:2 | D50: OTRO | E50: EXPLICITO | F50: Modelo CBX 89E | G50: =IF(B50="","",IFERROR(INDEX(ref_preguntas!$C$2:$C$200,MATCH(B50,ref_preguntas!$A$2:$A$200,0)),"ID no existe"))
A51: MH-004 | B51: P30 | C51: L_IMPRESORAS:2 | D51: CABLE_RED | E51: EXPLICITO | F51: Especificaciones de impresoras | G51: =IF(B51="","",IFERROR(INDEX(ref_preguntas!$C$2:$C$200,MATCH(B51,ref_preguntas!$A$2:$A$200,0)),"ID no existe"))
A52: MH-004 | B52: P45 | D52: SI | E52: EXPLICITO | F52: 2 repetidores | G52: =IF(B52="","",IFERROR(INDEX(ref_preguntas!$C$2:$C$200,MATCH(B52,ref_preguntas!$A$2:$A$200,0)),"ID no existe"))
A53: MH-004 | B53: P51 | D53: ID: Yomira Mora · Cliente: Gianfranco (equipo operativo) | E53: EXPLICITO | F53: Asistentes | G53: =IF(B53="","",IFERROR(INDEX(ref_preguntas!$C$2:$C$200,MATCH(B53,ref_preguntas!$A$2:$A$200,0)),"ID no existe"))
A54: MH-004 | B54: P12a | D54: SI | E54: EXPLICITO | F54: Pruebas de comandas | G54: =IF(B54="","",IFERROR(INDEX(ref_preguntas!$C$2:$C$200,MATCH(B54,ref_preguntas!$A$2:$A$200,0)),"ID no existe"))
...

Sheet kb_minuta_hallazgo
A1: minuta_id | B1: orden | C1: seccion | D1: texto | E1: pregunta_id | F1: regla_id
A2: MH-001 | B2: 1 | C2: ANTECEDENTE | D2: Entrega de impresoras.
A3: MH-001 | B3: 2 | C3: ANTECEDENTE | D3: Configuración de impresoras.
A4: MH-001 | B4: 3 | C4: ANTECEDENTE | D4: Creación de tienda en IDPos.
A5: MH-001 | B5: 4 | C5: ANTECEDENTE | D5: Creación de zonas de trabajo.
A6: MH-001 | B6: 5 | C6: ANTECEDENTE | D6: Acompañamiento en el llenado de información.
A7: MH-001 | B7: 6 | C7: DESARROLLO | D7: Para configurar las impresoras se hizo un mapeo de red.
A8: MH-001 | B8: 7 | C8: DESARROLLO | D8: Se armaron cables de red para cada impresora, excepto la de cocina porque está lejos del punto de red. | E8: U1 | F8: R06
A9: MH-001 | B9: 8 | C9: DESARROLLO | D9: Se creó la tienda en IDPos y se configuraron impresoras, zonas de trabajo y numeración de comprobantes.
A10: MH-002 | B10: 1 | C10: ANTECEDENTE | D10: Revisión del sistema de impresión del Raspberry y capacitación sobre creación de cupones.
A11: MH-002 | B11: 2 | C11: DESARROLLO | D11: Capacitación a la parte administrativa y caja sobre creación y uso de cupones. | F11: A04
A12: MH-002 | B12: 3 | C12: DESARROLLO | D12: Mapeo de red: los equipos estaban configurados directamente hacia el módem. | F12: R18
A13: MH-002 | B13: 4 | C13: DESARROLLO | D13: Mantenimiento a equipos de la red (TP-Link, módem, Raspberry). | F13: R27
A14: MH-002 | B14: 5 | C14: DESARROLLO | D14: Se armaron cables de red a medida, se cambiaron todos por Cat6 (más resistentes al calor) y se rotularon. | E14: P39 | F14: R09
A15: MH-002 | B15: 6 | C15: DESARROLLO | D15: Limpieza de tomas de energía. | F15: R27
A16: MH-002 | B16: 7 | C16: DESARROLLO | D16: Configuración del TP-Link para red de redundancia de internet. | E16: P16 | F16: R56
A17: MH-002 | B17: 8 | C17: DESARROLLO | D17: Configuración de impresora y sistema IDPos.
A18: MH-003 | B18: 1 | C18: ANTECEDENTE | D18: Los programas de impresión no funcionan hasta que se reinicia el internet.
A19: MH-003 | B19: 2 | C19: DESARROLLO | D19: Se realizó el mapeo de la red.
A20: MH-003 | B20: 3 | C20: OBSERVACION | D20: La computadora con los programas de impresión estaba conectada vía WiFi. | E20: P23 | F20: R11
A21: MH-003 | B21: 4 | C21: OBSERVACION | D21: La red de los repetidores compartía internet con las impresoras; no había conexión directa del módem a las impresoras. | F21: R12
A22: MH-003 | B22: 5 | C22: OBSERVACION | D22: Gabinete desorganizado con cable eléctrico libre; mantener cables eléctricos aislados. | E22: P40 | F22: R08
A23: MH-004 | B23: 1 | C23: ANTECEDENTE | D23: Cuentan con 2 impresoras (1 USB y 1 de red). | E23: P26
A24: MH-004 | B24: 2 | C24: OBSERVACION | D24: PC de caja conectada por adaptador WiFi; tiene puerto de red disponible y se probó la conexión directa por red. | E24: P23 | F24: R11
A25: MH-004 | B25: 3 | C25: OBSERVACION | D25: La comanda de bebidas se prepara en caja. | E25: P27
A26: MH-004 | B26: 4 | C26: OBSERVACION | D26: Tablets para meseros y para una segunda caja (rush).
A27: MH-004 | B27: 5 | C27: OBSERVACION | D27: Impresora de caja por USB; impresora de cocina por red (CBX 89E, IP 192.168.100.20). | E27: P30 | F27: R16
A28: MH-004 | B28: 6 | C28: OBSERVACION | D28: Dos repetidores Huawei (192.168.100.22 y 192.168.100.50). | E28: P45
A29: MH-005 | B29: 1 | C29: ANTECEDENTE | D29: El día previo se reportó que no había internet y que las impresoras no imprimían comandas ni comprobantes. | E29: P17
A30: MH-005 | B30: 2 | C30: DESARROLLO | D30: Solo la PC de caja 1 tenía internet (red Movistar). | E30: P23
A31: MH-005 | B31: 3 | C31: OBSERVACION | D31: Posible desconexión del cable de corriente del router de Claro; por eso no había internet. | E31: P34 | F31: R03
A32: MH-005 | B32: 4 | C32: OBSERVACION | D32: Un cable de red conectado al módem provocaba caídas de red en todos los dispositivos; se pasaron todos los equipos a la red Movistar. | F32: R29
A33: MH-005 | B33: 5 | C33: DESARROLLO | D33: Se reconfiguraron todas las impresoras en la red Movistar. | F33: A10
A34: MH-005 | B34: 6 | C34: OBSERVACION | D34: La red llegaba inestable a la barra 1 que reparte a las PC de caja; el switch de la barra fallaba y se reemplazó. | F34: R31
A35: MH-005 | B35: 7 | C35: DESARROLLO | D35: Se conectaron las tablets por WiFi a la red DORCHER CLIENTES (15/04/2023). | F35: R32
A36: MH-006 | B36: 1 | C36: ANTECEDENTE | D36: Se movió el cable de internet del segundo piso del router Movistar al de Claro; las impresoras dejaron de imprimir. | F36: R29
A37: MH-006 | B37: 2 | C37: DESARROLLO | D37: Se recableó el segundo piso (PC caja 3, impresoras de caja 3, barra 2 y cocina) para que todo quede en la red Claro. | F37: R29
A38: MH-006 | B38: 3 | C38: DESARROLLO | D38: Se reconfiguraron todos los equipos en la red Claro, se probó la impresión y la velocidad en cada PC de caja (~92–93 Mbps). | F38: A10
A39: MH-006 | B39: 4 | C39: DESARROLLO | D39: Se rotularon todos los cables de red de equipos e impresoras conectados al router. | F39: R30
A40: MH-006 | B40: 5 | C40: OBSERVACION | D40: Las 6 tablets tienen conectividad variable: algunas solo se conectan a DORCHER SISTEMAS y otras a DORCHER CLIENTES. | F40: R32
...

Sheet kb_minuta_recomendacion
A1: minuta_id | B1: orden | C1: tipo | D1: regla_id | E1: texto_original | F1: texto_regla
A2: MH-001 | B2: 1 | C2: RECOMENDACION | D2: R56 | E2: Ante caídas de la red principal es opcional tener un TP-Link 4G con chip para mantener la conexión de internet para las impresoras. | F2: =IF(D2="","",IFERROR(INDEX(kb_regla_recomendacion!$G$2:$G$200,MATCH(D2,kb_regla_recomendacion!$A$2:$A$200,0)),"Regla no existe"))
A3: MH-001 | B3: 2 | C3: RECOMENDACION | D3: R02 | E3: Es imprescindible contar con un kit Raspberry como parte de la virtualización de conexión a las impresoras e impresión. | F3: =IF(D3="","",IFERROR(INDEX(kb_regla_recomendacion!$G$2:$G$200,MATCH(D3,kb_regla_recomendacion!$A$2:$A$200,0)),"Regla no existe"))
A4: MH-001 | B4: 3 | C4: RECOMENDACION | D4: R03 | E4: Contar con un punto más de energía cerca del gabinete de cámaras u otro supresor de picos para la extensión de energía del Raspberry. | F4: =IF(D4="","",IFERROR(INDEX(kb_regla_recomendacion!$G$2:$G$200,MATCH(D4,kb_regla_recomendacion!$A$2:$A$200,0)),"Regla no existe"))
A5: MH-001 | B5: 4 | C5: RECOMENDACION | D5: R05 | E5: Un switch de 4 a 5 puertos para ampliar el punto de red en terraza. | F5: =IF(D5="","",IFERROR(INDEX(kb_regla_recomendacion!$G$2:$G$200,MATCH(D5,kb_regla_recomendacion!$A$2:$A$200,0)),"Regla no existe"))
A6: MH-001 | B6: 5 | C6: RECOMENDACION | D6: R06 | E6: Para la impresora de cocina contar con un punto de red más cerca. | F6: =IF(D6="","",IFERROR(INDEX(kb_regla_recomendacion!$G$2:$G$200,MATCH(D6,kb_regla_recomendacion!$A$2:$A$200,0)),"Regla no existe"))
A7: MH-001 | B7: 6 | C7: ACCION_ID | D7: R26 | E7: Realizar una segunda visita técnica para la conexión de impresoras. | F7: =IF(D7="","",IFERROR(INDEX(kb_regla_recomendacion!$G$2:$G$200,MATCH(D7,kb_regla_recomendacion!$A$2:$A$200,0)),"Regla no existe"))
A8: MH-001 | B8: 7 | C8: ACCION_CLIENTE | D8: A02 | E8: Confirmar recepción de la minuta de visita técnica. | F8: =IF(D8="","",IFERROR(INDEX(kb_regla_recomendacion!$G$2:$G$200,MATCH(D8,kb_regla_recomendacion!$A$2:$A$200,0)),"Regla no existe"))
A9: MH-001 | B9: 8 | C9: ACCION_CLIENTE | D9: R06 | E9: Tener el punto de red de la cocina cerca de su instalación para la siguiente visita. | F9: =IF(D9="","",IFERROR(INDEX(kb_regla_recomendacion!$G$2:$G$200,MATCH(D9,kb_regla_recomendacion!$A$2:$A$200,0)),"Regla no existe"))
A10: MH-001 | B10: 9 | C10: ACCION_CLIENTE | D10: A07 | E10: Llenado de la información del Excel brindado. | F10: =IF(D10="","",IFERROR(INDEX(kb_regla_recomendacion!$G$2:$G$200,MATCH(D10,kb_regla_recomendacion!$A$2:$A$200,0)),"Regla no existe"))
A11: MH-002 | B11: 1 | C11: RECOMENDACION | D11: R03 | E11: La toma de energía para los equipos en red debe ser independiente para evitar desconexiones al conectar la licuadora. | F11: =IF(D11="","",IFERROR(INDEX(kb_regla_recomendacion!$G$2:$G$200,MATCH(D11,kb_regla_recomendacion!$A$2:$A$200,0)),"Regla no existe"))
A12: MH-002 | B12: 2 | C12: RECOMENDACION | D12: R07 | E12: Adquirir un gabinete Nacional de pared de 4 RU (24 alto x 36 ancho x 35 prof.), colocarlo a 1.65 m del piso y contar con otro supresor de picos solo para los equipos del gabinete. | F12: =IF(D12="","",IFERROR(INDEX(kb_regla_recomendacion!$G$2:$G$200,MATCH(D12,kb_regla_recomendacion!$A$2:$A$200,0)),"Regla no existe"))
A13: MH-002 | B13: 3 | C13: RECOMENDACION | D13: R56 | E13: Contar con un chip solo para uso del TP-Link. | F13: =IF(D13="","",IFERROR(INDEX(kb_regla_recomendacion!$G$2:$G$200,MATCH(D13,kb_regla_recomendacion!$A$2:$A$200,0)),"Regla no existe"))
... A197: MH-044 | B197: 4 | C197: ACCION_CLIENTE | D197: A02 | E197: Confirmar recepción de la minuta. | F197: =IF(D197="","",IFERROR(INDEX(kb_regla_recomendacion!$G$2:$G$200,MATCH(D197,kb_regla_recomendacion!$A$2:$A$200,0)),"Regla no existe"))
F198: =IF(D198="","",IFERROR(INDEX(kb_regla_recomendacion!$G$2:$G$200,MATCH(D198,kb_regla_recomendacion!$A$2:$A$200,0)),"Regla no existe"))
F199: =IF(D199="","",IFERROR(INDEX(kb_regla_recomendacion!$G$2:$G$200,MATCH(D199,kb_regla_recomendacion!$A$2:$A$200,0)),"Regla no existe"))
F200: =IF(D200="","",IFERROR(INDEX(kb_regla_recomendacion!$G$2:$G$200,MATCH(D200,kb_regla_recomendacion!$A$2:$A$200,0)),"Regla no existe"))
F201: =IF(D201="","",IFERROR(INDEX(kb_regla_recomendacion!$G$2:$G$200,MATCH(D201,kb_regla_recomendacion!$A$2:$A$200,0)),"Regla no existe"))
F202: =IF(D202="","",IFERROR(INDEX(kb_regla_recomendacion!$G$2:$G$200,MATCH(D202,kb_regla_recomendacion!$A$2:$A$200,0)),"Regla no existe"))
F203: =IF(D203="","",IFERROR(INDEX(kb_regla_recomendacion!$G$2:$G$200,MATCH(D203,kb_regla_recomendacion!$A$2:$A$200,0)),"Regla no existe"))
F204: =IF(D204="","",IFERROR(INDEX(kb_regla_recomendacion!$G$2:$G$200,MATCH(D204,kb_regla_recomendacion!$A$2:$A$200,0)),"Regla no existe"))
F205: =IF(D205="","",IFERROR(INDEX(kb_regla_recomendacion!$G$2:$G$200,MATCH(D205,kb_regla_recomendacion!$A$2:$A$200,0)),"Regla no existe"))
F206: =IF(D206="","",IFERROR(INDEX(kb_regla_recomendacion!$G$2:$G$200,MATCH(D206,kb_regla_recomendacion!$A$2:$A$200,0)),"Regla no existe"))
F207: =IF(D207="","",IFERROR(INDEX(kb_regla_recomendacion!$G$2:$G$200,MATCH(D207,kb_regla_recomendacion!$A$2:$A$200,0)),"Regla no existe"))
F208: =IF(D208="","",IFERROR(INDEX(kb_regla_recomendacion!$G$2:$G$200,MATCH(D208,kb_regla_recomendacion!$A$2:$A$200,0)),"Regla no existe"))
F209: =IF(D209="","",IFERROR(INDEX(kb_regla_recomendacion!$G$2:$G$200,MATCH(D209,kb_regla_recomendacion!$A$2:$A$200,0)),"Regla no existe"))
... F347: =IF(D347="","",IFERROR(INDEX(kb_regla_recomendacion!$G$2:$G$200,MATCH(D347,kb_regla_recomendacion!$A$2:$A$200,0)),"Regla no existe"))

Sheet kb_minuta_equipo
A1: minuta_id | B1: tipo_equipo | C1: marca | D1: modelo | E1: ip | F1: conexion | G1: area | H1: cantidad | I1: nota
A2: MH-001 | B2: printer | F2: CABLE_RED | I2: Impresoras entregadas y configuradas; la de cocina quedó pendiente por falta de punto de red
A3: MH-001 | B3: camera | I3: Hay un gabinete de cámaras
A4: MH-002 | B4: modem | H4: 1 | I4: Los equipos estaban configurados directo al módem
A5: MH-002 | B5: router | C5: TP-Link | H5: 1 | I5: Configurado como red de redundancia de internet (4G)
A6: MH-002 | B6: raspberry | C6: Raspberry | H6: 1 | I6: Sistema de impresión
A7: MH-002 | B7: printer | I7: Configurada con IDPos
A8: MH-003 | B8: computer | F8: WIFI | G8: CAJA | H8: 1 | I8: PC con los programas de impresión
A9: MH-003 | B9: repetidor | F9: WIFI | I9: Compartían red con las impresoras
A10: MH-003 | B10: printer | G10: BAR | H10: 1 | I10: Impresora de barra
A11: MH-004 | B11: router | C11: Huawei | D11: OptiXstar HG8145X6-10 | E11: 192.168.100.1 | G11: CAJA | H11: 1 | I11: Router principal (Claro)
A12: MH-004 | B12: computer | E12: 192.168.100.13 | F12: WIFI | G12: CAJA | H12: 1 | I12: Tiene puerto de red libre
A13: MH-004 | B13: printer | F13: USB | G13: CAJA | H13: 1 | I13: Conectada a la PC de caja
A14: MH-004 | B14: printer | C14: CBX | D14: CBX-POS89E | E14: 192.168.100.20 | F14: CABLE_RED | G14: COCINA | H14: 1 | I14: IP fija
A15: MH-004 | B15: repetidor | C15: Huawei | E15: 192.168.100.22 | F15: WIFI | H15: 1
A16: MH-004 | B16: repetidor | C16: Huawei | E16: 192.168.100.50 | F16: WIFI | H16: 1
A17: MH-004 | B17: tablet | F17: WIFI | G17: SALON_1 | I17: Tablets para meseros y segunda caja (rush)
A18: MH-005 | B18: router | H18: 2 | I18: Dos routers: Claro y Movistar
A19: MH-005 | B19: computer | F19: CABLE_RED | G19: CAJA | H19: 3 | I19: PC caja 1, 2 y 3
A20: MH-005 | B20: switch | F20: CABLE_RED | G20: BAR | H20: 1 | I20: Switch de la barra 1 con falla; reemplazado por uno de ID
A21: MH-005 | B21: tablet | F21: WIFI | I21: Tablets de meseras en red DORCHER CLIENTES
A22: MH-006 | B22: computer | F22: CABLE_RED | G22: CAJA | H22: 3 | I22: ~92–93 Mbps en cada PC
A23: MH-006 | B23: printer | F23: CABLE_RED | G23: CAJA | H23: 3 | I23: Impresoras de caja 1, 2 y 3
A24: MH-006 | B24: printer | F24: CABLE_RED | G24: BAR | H24: 2 | I24: Barra 1 (piso 1) y barra 2 (piso 2)
A25: MH-006 | B25: printer | F25: CABLE_RED | G25: COCINA | H25: 1
A26: MH-006 | B26: tablet | F26: WIFI | H26: 6 | I26: Redes DORCHER SISTEMAS y DORCHER CLIENTES
A27: MH-007 | B27: pos | C27: Sunmi | F27: WIFI | H27: 1 | I27: Monitor Summi con chip Entel 4G
A28: MH-007 | B28: router | C28: TP-Link | H28: 1 | I28: Router 4G con chip (10 GB), 3 puertos, respaldo automático
A29: MH-008 | B29: raspberry | C29: Raspberry | F29: CABLE_RED | G29: OTRO | H29: 1 | I29: En la barra de Bodegón
A30: MH-008 | B30: printer | F30: CABLE_RED | G30: OTRO | H30: 3 | I30: Recepción, Bodegón y Lagar
A31: MH-008 | B31: computer | F31: WIFI | G31: CAJA | H31: 1 | I31: PC de caja por WiFi
A32: MH-008 | B32: computer | G32: OTRO | H32: 1 | I32: PC de recepción (zona horaria corregida)
A33: MH-008 | B33: modem | C33: Hughesnet | H33: 1 | I33: Internet satelital
A34: MH-009 | B34: router | G34: CAJA | H34: 1 | I34: Router principal con fibra óptica
A35: MH-009 | B35: printer | F35: USB | G35: CAJA | H35: 1 | I35: Impresora de caja USB
A36: MH-009 | B36: printer | E36: 192.168.0.241 | F36: CABLE_RED | G36: CAJA | H36: 1 | I36: El PDF la rotula 'Impresora de Caja (RED)'; verificar si es la de cocina-brasas
A37: MH-009 | B37: tablet | F37: WIFI
A38: MH-010 | B38: printer | E38: 192.168.1.111 | F38: CABLE_RED | G38: CAJA | H38: 1 | I38: Conector holgado
A39: MH-010 | B39: printer | E39: 192.168.1.110 | F39: CABLE_RED | G39: BRASAS | H39: 1 | I39: Conector holgado
A40: MH-010 | B40: printer | E40: 192.168.1.100 | F40: CABLE_RED | G40: COCINA | H40: 1 | I40: Conector holgado
...

Sheet kb_minuta_evidencia
A1: minuta_id | B1: codigo_evidencia | C1: descripcion | D1: archivo_o_pagina | E1: nota
A2: MH-001 | B2: MAPA | C2: Network Topology | D2: sicilia.pdf
A3: MH-002 | B3: MAPA | C3: Topology Network (a implementar gabinete y energía) | D3: donoscar.pdf
A4: MH-003 | B4: E1 | C4: Velocidad de internet | D4: barrio.pdf
A5: MH-003 | B5: E6 | C5: Fotos de la red | D5: barrio.pdf
A6: MH-003 | B6: MAPA | C6: Topology Network de equipos a implementar | D6: barrio.pdf
A7: MH-004 | B7: E1 | C7: Especificaciones de velocidad: descarga 91.50 Mbps, subida 92.49 Mbps | D7: rock.pdf
A8: MH-004 | B8: E3 | C8: Especificaciones del router principal: gateway 192.168.100.1 | D8: rock.pdf | E8: Ocultar credenciales de la etiqueta
A9: MH-004 | B9: E5 | C9: Especificaciones de impresoras: Caja (USB) y Cocina (CBX 89E, IP 192.168.100.20) | D9: rock.pdf
A10: MH-004 | B10: E8 | C10: Mapeo de red: 192.168.100.1 router, .13 PC caja, .20 impresora cocina, .22 y .50 repetidores | D10: rock.pdf
A11: MH-004 | B11: E9 | C11: Imágenes de zonas: salones del piso 2 y piso 3 | D11: rock.pdf
A12: MH-004 | B12: VIDEO | C12: CAJA Y ROUTER PRINCIPAL.mp4 | E12: Video externo
A13: MH-004 | B13: VIDEO | C13: REPETIDORES.mp4 | E13: Video externo
A14: MH-004 | B14: VIDEO | C14: SELFTEST.mp4 | E14: Video externo
A15: MH-005 | B15: E1 | C15: Speedtest antes y después del cambio de switch (94.01 / 94.43 Mbps)
A16: MH-005 | B16: E2 | C16: Router antes y después de conectarlo
A17: MH-006 | B17: E1 | C17: Speedtest de PC caja 1, 2 y 3 (~92–93 Mbps)
A18: MH-006 | B18: E5 | C18: Pruebas de impresión: barra 2, caja 3, cocina, caja 1, caja 2 y barra 1
A19: MH-006 | B19: E6 | C19: Cables rotulados en el router
A20: MH-006 | B20: OTRA | C20: Redes WiFi de las tablets
A21: MH-007 | B21: MAPA | C21: Topology Network
A22: MH-008 | B22: E8 | C22: Mapeo de red: Lagar, Recepción, Bodegón
A23: MH-008 | B23: MAPA | C23: Topology Network
A24: MH-009 | B24: E9 | C24: Zonas: salón 01, salón 02, caja, cocina-brasas
A25: MH-009 | B25: VIDEO | C25: Video del local
A26: MH-009 | B26: E1 | C26: Speedtest 493.11 Mbps
